Workbook

Sheet Summary
A1: PMS (Planned Maintenance System) — Additional UAT Test Cases
A2: Additional Test Cases Beyond Original 405 — Comprehensive Gap Coverage
A3: Generated: 18 Mar 2026
A5: MODULE | B5: SHEET NAME | C5: TOTAL TEST CASES | D5: PASSED | E5: FAILED | F5: PASS RATE (%)
A6: 1. Components — Additional | B6: Components Additional | C6: 25 | D6: =COUNTIF('Components Additional'!I:I,"Pass") | E6: =COUNTIF('Components Additional'!I:I,"Fail") | F6: =IF(C6=0,0,ROUND(D6/C6*100,1))
A7: 2. Work Orders — Additional | B7: Work Orders Additional | C7: 30 | D7: =COUNTIF('Work Orders Additional'!I:I,"Pass") | E7: =COUNTIF('Work Orders Additional'!I:I,"Fail") | F7: =IF(C7=0,0,ROUND(D7/C7*100,1))
A8: 3. Running Hours — Additional | B8: Running Hours Additional | C8: 20 | D8: =COUNTIF('Running Hours Additional'!I:I,"Pass") | E8: =COUNTIF('Running Hours Additional'!I:I,"Fail") | F8: =IF(C8=0,0,ROUND(D8/C8*100,1))
A9: 4. Spares — Additional | B9: Spares Additional | C9: 25 | D9: =COUNTIF('Spares Additional'!I:I,"Pass") | E9: =COUNTIF('Spares Additional'!I:I,"Fail") | F9: =IF(C9=0,0,ROUND(D9/C9*100,1))
A10: 5. Stores — Additional | B10: Stores Additional | C10: 25 | D10: =COUNTIF('Stores Additional'!I:I,"Pass") | E10: =COUNTIF('Stores Additional'!I:I,"Fail") | F10: =IF(C10=0,0,ROUND(D10/C10*100,1))
A11: 6. Reports — Additional | B11: Reports Additional | C11: 80 | D11: =COUNTIF('Reports Additional'!I:I,"Pass") | E11: =COUNTIF('Reports Additional'!I:I,"Fail") | F11: =IF(C11=0,0,ROUND(D11/C11*100,1))
A12: 7. Dashboard — Additional | B12: Dashboard Additional | C12: 20 | D12: =COUNTIF('Dashboard Additional'!I:I,"Pass") | E12: =COUNTIF('Dashboard Additional'!I:I,"Fail") | F12: =IF(C12=0,0,ROUND(D12/C12*100,1))
A13: 8. Defects Module (NEW) | B13: Defects Module | C13: 40 | D13: =COUNTIF('Defects Module'!I:I,"Pass") | E13: =COUNTIF('Defects Module'!I:I,"Fail") | F13: =IF(C13=0,0,ROUND(D13/C13*100,1))
A14: 9. Certificates & Surveys (NEW) | B14: Certificates & Surveys | C14: 25 | D14: =COUNTIF('Certificates & Surveys'!I:I,"Pass") | E14: =COUNTIF('Certificates & Surveys'!I:I,"Fail") | F14: =IF(C14=0,0,ROUND(D14/C14*100,1))
A15: 10. Admin Module (NEW) | B15: Admin Module | C15: 30 | D15: =COUNTIF('Admin Module'!I:I,"Pass") | E15: =COUNTIF('Admin Module'!I:I,"Fail") | F15: =IF(C15=0,0,ROUND(D15/C15*100,1))
A16: 11. Modify PMS & CRs (NEW) | B16: Modify PMS & Change Requests | C16: 25 | D16: =COUNTIF('Modify PMS & Change Requests'!I:I,"Pass") | E16: =COUNTIF('Modify PMS & Change Requests'!I:I,"Fail") | F16: =IF(C16=0,0,ROUND(D16/C16*100,1))
A17: 12. Cross-Module (NEW) | B17: Cross-Module & Integration | C17: 20 | D17: =COUNTIF('Cross-Module & Integration'!I:I,"Pass") | E17: =COUNTIF('Cross-Module & Integration'!I:I,"Fail") | F17: =IF(C17=0,0,ROUND(D17/C17*100,1))
A18: TOTAL | C18: =SUM(C6:C17) | D18: =SUM(D6:D17) | E18: =SUM(E6:E17) | F18: =IF(C18=0,0,ROUND(D18/C18*100,1))
A20: TEST ENVIRONMENT DETAILS
A21: Application | B21: PMS — Planned Maintenance System
A22: Version | B22: v1.0 (UAT)
A23: Environment | B23: UAT / Staging
A24: URL | B24: [To be provided]
A25: Browser | B25: Chrome (latest), Firefox (latest), Edge (latest)
A26: Test Period | B26: [Start Date] to [End Date]
A27: Test Lead | B27: [Name]
A29: TESTING INSTRUCTIONS
A30: 1. Navigate to the relevant module sheet for the area being tested.
A31: 2. Follow the Test Steps column exactly as described.
A32: 3. Use the Test Data provided (or substitute equivalent valid/invalid data).
A33: 4. Compare the actual result with the Expected Result.
A34: 5. Mark Pass/Fail in column I. Use "Blocked" if a prerequisite prevents testing.
A35: 6. Record any issues, bugs, or observations in the Comments column.
A36: 7. Enter your name and the test date in columns K and L.
A37: 8. Priority guide: High = must pass for go-live, Medium = important, Low = nice-to-have.
A39: KNOWN ISSUES / LIMITATIONS
A40: (To be updated during testing)

Sheet Components Additional
A1: Test Case ID | B1: Module/Section | C1: Test Scenario | D1: Priority | E1: Test Steps | F1: Test Data | G1: Expected Result | H1: Actual Result | I1: Pass/Fail | J1: Comments/Issues | K1: Tester Name | L1: Test Date | M1: How to Test
A2: COMP-051 | B2: Tree View | C2: Expand all tree nodes | D2: Medium | E2: 1. Navigate to Components 2. Click "Expand All" button 3. Verify all nodes expanded | F2: N/A | G2: All tree nodes expand showing full SFI hierarchy | M2: HOW TO TEST: 1. Log in to RSMS and click "PMS" in the top menu bar. 2. In the left sidebar, click "Components" to open the Components page. 3. Select a vessel from the vessel dropdown (e.g., "Vessel 11"). 4. In the left panel, locate the "Expand All" button (typically at the top of the tree panel). 5. Click the "Expand All" button. 6. VERIFY: All tree nodes expand, revealing the full SFI hierarchy down to the lowest level. 7. VERIFY: Every parent node shows its children, sub-children, and so on. 8. VERIFY: The tree can be scrolled to see all expanded items.
A3: COMP-052 | B3: Tree View | C3: Collapse all tree nodes | D3: Medium | E3: 1. Expand all nodes 2. Click "Collapse All" 3. Verify only top-level nodes visible | F3: N/A | G3: Tree collapses to show only 8 main SFI categories | M3: HOW TO TEST: 1. Navigate to PMS > Components and select a vessel. 2. First click "Expand All" to open all tree nodes. 3. Then click the "Collapse All" button. 4. VERIFY: Only the top-level SFI categories remain visible (e.g., 1-Engine, 2-Deck, etc.). 5. VERIFY: No child components are visible under any category. 6. VERIFY: Clicking a top-level node expands only that branch.
A4: COMP-053 | B4: Tree View | C4: Search component in tree by SFI code | D4: Medium | E4: 1. Enter SFI code in tree search 2. Verify tree filters to matching nodes | F4: Search: "7.1" | G4: Tree filters to show only components matching SFI code 7.1.x | M4: HOW TO TEST: 1. Navigate to PMS > Components and select a vessel. 2. Locate the search input field above or within the component tree panel. 3. Type "7.1" into the search field. 4. VERIFY: The tree filters to show only components whose SFI code starts with or contains "7.1". 5. VERIFY: Parent nodes leading to matching components are also visible for context. 6. VERIFY: Non-matching branches are hidden. 7. Clear the search and VERIFY the full tree reappears.
A5: COMP-054 | B5: Tree View | C5: Search component in tree by maker | D5: Low | E5: 1. Enter maker name in tree search 2. Verify matching components highlighted | F5: Search: "Caterpillar" | G5: Tree filters to components with maker matching search term | M5: HOW TO TEST: 1. Navigate to PMS > Components and select a vessel. 2. In the tree search field, type a maker name such as "Caterpillar". 3. VERIFY: Components with that maker are highlighted or the tree filters to show only matching components. 4. VERIFY: If no results, the tree shows an appropriate "No results" message. 5. Clear the search to restore the full tree.
A6: COMP-055 | B6: Tree View | C6: Drag-and-drop reorder components (Edit mode) | D6: Medium | E6: 1. Click "Edit" button on tree 2. Drag a component to new position 3. Drop and verify reorder | F6: N/A | G6: Component moved to new position. Tree order updated. | M6: HOW TO TEST: 1. Navigate to PMS > Components and select a vessel. 2. If available, click the "Edit" or "Reorder" button on the tree panel to enable edit mode. 3. Click and hold on a component node in the tree. 4. Drag it to a new position (e.g., above or below a sibling). 5. Drop the component. 6. VERIFY: The component appears at the new position. 7. VERIFY: The new order persists after refreshing the page. 8. Exit edit mode when done.
A7: COMP-056 | B7: Component Details | C7: View Section B - Running Hours & Condition | D7: Medium | E7: 1. Select component with RH tracking 2. Expand Section B 3. Verify RH display | F7: Component with RH | G7: Section B shows: Current RH, Counter Type, Source, Last Updated | M7: HOW TO TEST: 1. Navigate to PMS > Components and select a vessel. 2. Click on a component in the tree that has Running Hours tracking (e.g., Main Engine). 3. In the detail panel on the right, scroll to or expand "Section B - Running Hours & Condition". 4. VERIFY: Current Running Hours value is displayed. 5. VERIFY: Counter Type is shown (e.g., "Hours"). 6. VERIFY: Source of last update is indicated. 7. VERIFY: Last Updated date/time is displayed.
A8: COMP-057 | B8: Component Details | C8: View Section D - Maintenance History drill-down | D8: High | E8: 1. Select component 2. Expand Section D - Maintenance History 3. Click on a completed WO row | F8: N/A | G8: Work Order Viewer Sheet opens showing full completed WO form (read-only) | M8: HOW TO TEST: 1. Navigate to PMS > Components and select a vessel. 2. Click on a component that has completed work orders. 3. Scroll to "Section D - Maintenance History" in the detail panel. 4. VERIFY: A list of completed work orders is shown with dates and job titles. 5. Click on any completed WO row. 6. VERIFY: The Work Order Viewer opens, showing the full completed WO form in read-only mode. 7. VERIFY: All sections (Part A, Part B) are visible with completion data.
A9: COMP-058 | B9: Component Details | C9: View Section E - Linked Spares with location popover | D9: Medium | E9: 1. Select component 2. Expand Section E - Spares 3. Click location icon on a spare | F9: N/A | G9: Popover shows storage locations with quantities per location (Location A, Location B) | M9: HOW TO TEST: 1. Navigate to PMS > Components and select a vessel. 2. Click on a component that has linked spare parts. 3. Scroll to "Section E - Spares" in the detail panel. 4. VERIFY: Linked spares are listed with names and ROB (Remaining on Board). 5. Click the location icon or link on any spare. 6. VERIFY: A popover or tooltip appears showing storage locations (Location A, Location B) with quantities for each.
A10: COMP-059 | B10: Component Details | C10: View Section F - Drawings & Manuals | D10: Low | E10: 1. Select component 2. Expand Section F 3. Verify documents listed | F10: N/A | G10: Section shows uploaded drawings, manuals, and technical documents | M10: HOW TO TEST: 1. Navigate to PMS > Components and select a vessel. 2. Click on a component. 3. Scroll to "Section F - Drawings & Manuals". 4. VERIFY: Any uploaded drawings or manuals are listed with file names. 5. VERIFY: Each document has a download or view link. 6. If no documents are uploaded, VERIFY an appropriate empty state is shown.
A11: COMP-060 | B11: Component Details | C11: View Section G - Classification & Regulatory | D11: Medium | E11: 1. Select component 2. Expand Section G 3. Verify classification data | F11: N/A | G11: Shows certificates, survey types, and due dates linked to component | M11: HOW TO TEST: 1. Navigate to PMS > Components and select a vessel. 2. Click on a component (preferably one linked to class surveys). 3. Scroll to "Section G - Classification & Regulatory". 4. VERIFY: Linked certificates or survey types are shown. 5. VERIFY: Due dates are displayed where applicable. 6. VERIFY: Any classification society references are visible.
A12: COMP-061 | B12: Component Details | C12: View Section H - Requisitions | D12: Low | E12: 1. Select component 2. Expand Section H 3. Verify procurement requests | F12: N/A | G12: Shows ongoing procurement/requisition requests for this component | M12: HOW TO TEST: 1. Navigate to PMS > Components and select a vessel. 2. Click on a component. 3. Scroll to "Section H - Requisitions". 4. VERIFY: Any ongoing or historical procurement/requisition requests are listed. 5. VERIFY: Status of each requisition is shown. 6. If none exist, VERIFY empty state message is displayed.
A13: COMP-062 | B13: Modify Mode | C13: Enter Modify mode on Components page | D13: High | E13: 1. Navigate to Modify PMS or add ?modify=1 2. Verify modify mode indicator 3. Check fields become editable | F13: N/A | G13: Modify mode activates. Sticky footer appears. Editable fields are interactive. | M13: HOW TO TEST: 1. Log in as a user with modify permissions (Sail Admin or CE). 2. Navigate to PMS > Modify PMS from the sidebar. 3. VERIFY: A "Modify Mode" indicator/banner appears at the top or bottom of the page. 4. Navigate to Components within modify mode. 5. Click on a component. 6. VERIFY: Certain fields (e.g., Maker, Model) become editable with input fields instead of static text. 7. VERIFY: A sticky footer bar appears with "Review Changes" and "Discard" buttons.
... A26: COMP-075 | B26: Edge Cases | C26: Component with maximum depth nesting | D26: Low | E26: 1. Navigate to component with deep nesting (5+ levels) 2. Expand all levels 3. Verify display | F26: Deeply nested component | G26: All nesting levels display correctly with proper indentation | M26: HOW TO TEST: 1. Navigate to PMS > Components and select a vessel. 2. Find a component hierarchy with deep nesting (5 or more levels). 3. Expand each level progressively. 4. VERIFY: Each nesting level is properly indented in the tree. 5. VERIFY: The deepest component can be selected and its details viewed. 6. VERIFY: No UI overflow or layout issues at deep nesting levels.

Sheet Work Orders Additional
A1: Test Case ID | B1: Module/Section | C1: Test Scenario | D1: Priority | E1: Test Steps | F1: Test Data | G1: Expected Result | H1: Actual Result | I1: Pass/Fail | J1: Comments/Issues | K1: Tester Name | L1: Test Date | M1: How to Test
A2: WO-169 | B2: Postpone Dialog | C2: Postpone due work order with all fields | D2: High | E2: 1. Open Due WO 2. Click Postpone icon 3. Enter reason, select Authorized By, Duration 4. Save | F2: Reason: "Spare parts awaited" Auth: Superintendent Duration: 2 weeks | G2: WO postponed. New due date set. Postponement logged with all details. | M2: HOW TO TEST: 1. Navigate to PMS > Work Orders and select a vessel. 2. Go to the "Due" tab to find work orders that are currently due. 3. Click the Postpone icon (clock/calendar icon) on a due work order row. 4. VERIFY: The Postpone dialog opens. 5. Enter a reason: "Spare parts awaited". 6. Select "Superintendent" from the Authorized By dropdown. 7. Select "2 weeks" from the Duration options. 8. Click Save/Confirm. 9. VERIFY: The work order status updates and the new due date is 2 weeks from today. 10. VERIFY: The postponement details are logged and visible in the WO history.
A3: WO-170 | B3: Postpone Dialog | C3: Postpone without reason blocked | D3: High | E3: 1. Open Due WO 2. Click Postpone 3. Leave reason empty 4. Try to save | F3: Reason: empty | G3: Validation error: Reason is required. Save blocked. | M3: HOW TO TEST: 1. Navigate to PMS > Work Orders > Due tab. 2. Click the Postpone icon on a due WO. 3. Leave the "Reason" field empty. 4. Select an Authorized By and Duration. 5. Click Save. 6. VERIFY: A validation error appears indicating "Reason is required". 7. VERIFY: The save action is blocked until a reason is provided.
A4: WO-171 | B4: Postpone Dialog | C4: Postpone with Inform Office checkbox | D4: Medium | E4: 1. Open Postpone dialog 2. Check "Inform Office" checkbox 3. Optionally attach document 4. Save | F4: Inform Office: checked | G4: Postponement saved with office notification flag. Document attached if provided. | M4: HOW TO TEST: 1. Open the Postpone dialog on a due WO. 2. Fill in reason and authorized by. 3. Check the "Inform Office" checkbox. 4. Optionally attach a supporting document. 5. Click Save. 6. VERIFY: Postponement is saved successfully. 7. VERIFY: The "Inform Office" flag is recorded with the postponement. 8. VERIFY: If a document was attached, it appears in the postponement record.
A5: WO-172 | B5: Postpone Dialog | C5: Postpone duration options | D5: Medium | E5: 1. Open Postpone dialog 2. Check available duration options 3. Select each option and verify date calculation | F5: Durations: 1 Day, 1 Week, 2 Weeks, 1 Month | G5: Each duration option correctly calculates the new due date from today. | M5: HOW TO TEST: 1. Open the Postpone dialog on a due WO. 2. VERIFY: Duration options include at least: 1 Day, 1 Week, 2 Weeks, 1 Month. 3. Select "1 Day" and VERIFY the new due date preview shows tomorrow. 4. Select "1 Week" and VERIFY 7 days from today. 5. Select "2 Weeks" and VERIFY 14 days. 6. Select "1 Month" and VERIFY 1 calendar month ahead. 7. Confirm the date calculation is correct for each option.
A6: WO-173 | B6: Postpone Dialog | C6: Cancel postpone action | D6: Low | E6: 1. Open Postpone dialog 2. Fill in some fields 3. Click Cancel | F6: N/A | G6: Dialog closes. No postponement recorded. WO status unchanged. | M6: HOW TO TEST: 1. Open the Postpone dialog on a due WO. 2. Fill in a reason and select a duration. 3. Click "Cancel" or the X button. 4. VERIFY: The dialog closes. 5. VERIFY: The WO status has not changed. 6. VERIFY: No postponement record was created.
A7: WO-174 | B7: Bulk Approve | C7: Open Bulk Approve modal | D7: High | E7: 1. Navigate to Pending Approval tab or Dashboard 2. Click "Bulk Approve" button 3. Verify modal opens | F7: Must have pending WOs | G7: Bulk Approve modal opens showing list of all pending approval WOs | M7: HOW TO TEST: 1. Navigate to PMS > Work Orders > "Pending Approval" tab (or the Dashboard pending section). 2. VERIFY: There are work orders pending approval. 3. Click the "Bulk Approve" button. 4. VERIFY: A modal dialog opens. 5. VERIFY: The modal shows a list of all WOs pending approval with checkboxes. 6. VERIFY: Each row shows WO number, component, job title, and completion date.
A8: WO-175 | B8: Bulk Approve | C8: Select all WOs in Bulk Approve | D8: High | E8: 1. Open Bulk Approve modal 2. Click "Select All" checkbox 3. Verify all items selected | F8: 10+ pending WOs | G8: All WOs selected. Count indicator shows total selected. | M8: HOW TO TEST: 1. Open the Bulk Approve modal (must have multiple pending WOs). 2. Click the "Select All" checkbox in the header row. 3. VERIFY: All individual WO checkboxes are checked. 4. VERIFY: A count indicator updates (e.g., "10 of 10 selected"). 5. Uncheck "Select All" and VERIFY all checkboxes are unchecked.
A9: WO-176 | B9: Bulk Approve | C9: Search within Bulk Approve modal | D9: Medium | E9: 1. Open Bulk Approve modal 2. Type search term 3. Verify filtered list | F9: Search: "Main Engine" | G9: List filters to show only WOs matching search term | M9: HOW TO TEST: 1. Open the Bulk Approve modal with multiple pending WOs. 2. Locate the search input within the modal. 3. Type "Main Engine". 4. VERIFY: The list filters to show only WOs related to "Main Engine". 5. VERIFY: Non-matching WOs are hidden. 6. Clear the search and VERIFY all WOs reappear.
A10: WO-177 | B10: Bulk Approve | C10: View WO details from Bulk Approve (Eye icon) | D10: Medium | E10: 1. Open Bulk Approve modal 2. Click Eye icon on a WO 3. Verify details shown | F10: N/A | G10: WO details panel shows completion data for review before approval. | M10: HOW TO TEST: 1. Open the Bulk Approve modal. 2. Click the Eye/View icon on any WO row. 3. VERIFY: A details panel or expandable section shows the WO completion data. 4. VERIFY: You can see completion details (dates, work carried out, parts used) for review. 5. VERIFY: You can close the details and return to the list view.
A11: WO-178 | B11: Bulk Approve | C11: Approve selected WOs | D11: High | E11: 1. Select 5 WOs 2. Click "Approve Selected" 3. Confirm action | F11: 5 WOs selected | G11: All 5 WOs approved. Status → Completed. Success message with count. | M11: HOW TO TEST: 1. Open the Bulk Approve modal. 2. Select 5 WOs by checking their checkboxes. 3. Click "Approve Selected". 4. VERIFY: A confirmation dialog appears (e.g., "Approve 5 work orders?"). 5. Confirm the action. 6. VERIFY: A success message shows "5 work orders approved". 7. VERIFY: The approved WOs are removed from the pending list. 8. Navigate to Completed tab and VERIFY the 5 WOs appear there.
A12: WO-179 | B12: Bulk Approve | C12: Reject selected WOs with bulk comments | D12: High | E12: 1. Select 3 WOs 2. Click "Reject Selected" 3. Enter rejection comments 4. Confirm | F12: Comments: "Incomplete documentation" | G12: All 3 WOs rejected with same comments. Status reverts. Notification sent. | M12: HOW TO TEST: 1. Open the Bulk Approve modal. 2. Select 3 WOs. 3. Click "Reject Selected". 4. VERIFY: A comments/reason input appears. 5. Enter "Incomplete documentation". 6. Confirm the rejection. 7. VERIFY: All 3 WOs are rejected with the shared comment. 8. VERIFY: The WOs return to a state where they can be re-completed by the vessel.
A13: WO-180 | B13: Unplanned WO | C13: Create unplanned work order | D13: High | E13: 1. Click "Add Job" → Unplanned option 2. Select component 3. Fill job details manually 4. Submit | F13: Component: Main Engine Job: Emergency repair | G13: Unplanned WO created without linked job template. Marked as "Unplanned" type. | M13: HOW TO TEST: 1. Navigate to PMS > Work Orders. 2. Click "Add Job" or "Create Work Order" button. 3. Select "Unplanned" or "Breakdown" as the work order type. 4. Select a component (e.g., Main Engine). 5. Fill in the job title: "Emergency repair". 6. Fill in other required fields. 7. Submit. 8. VERIFY: The work order is created and appears in the WO list. 9. VERIFY: It is marked as "Unplanned" type in the list view.
... A31: WO-198 | B31: Cross-Field | C31: Completion date before start date validation | D31: Medium | E31: 1. Open WO completion 2. Set completion date before start date 3. Try to save | F31: Start: 15-Mar, Completion: 10-Mar | G31: Validation error: "Completion date cannot be before start date." | M31: HOW TO TEST: 1. Open a WO for completion. 2. Set Start Date to 15-Mar-2026. 3. Set Completion Date to 10-Mar-2026 (before start). 4. Try to save or submit. 5. VERIFY: A validation error appears: "Completion date cannot be before start date." 6. VERIFY: The form does not submit until the dates are corrected.

Sheet Running Hours Additional
A1: Test Case ID | B1: Module/Section | C1: Test Scenario | D1: Priority | E1: Test Steps | F1: Test Data | G1: Expected Result | H1: Actual Result | I1: Pass/Fail | J1: Comments/Issues | K1: Tester Name | L1: Test Date | M1: How to Test
A2: RH-036 | B2: History Tab | C2: Navigate to History tab | D2: Medium | E2: 1. Navigate to Running Hours 2. Click History tab 3. Verify two-step interface | F2: N/A | G2: History tab shows: Step 1 - Search/Select component, Step 2 - Audit log | M2: HOW TO TEST: 1. Navigate to PMS > Running Hours and select a vessel. 2. Click the "History" tab. 3. VERIFY: The tab shows a two-step interface. 4. VERIFY: Step 1 shows a search/select component interface. 5. VERIFY: Step 2 (audit log) is not visible until a component is selected.
A3: RH-037 | B3: History Tab | C3: Search component in history | D3: Medium | E3: 1. Go to History tab 2. Type component name in search 3. Select component | F3: Search: "Main Engine" | G3: Components matching search shown. Select one to view history. | M3: HOW TO TEST: 1. Navigate to PMS > Running Hours > History tab. 2. In the search field, type "Main Engine". 3. VERIFY: Matching components appear in a dropdown or list. 4. Click on a matching component. 5. VERIFY: The history/audit log for that component loads in Step 2.
A4: RH-038 | B4: History Tab | C4: Filter history by date range | D4: Medium | E4: 1. Select component in History 2. Set Date From and Date To 3. Verify filtered results | F4: From: 01-Jan-2026, To: 31-Mar-2026 | G4: Only history entries within date range displayed | M4: HOW TO TEST: 1. In RH History tab, select a component. 2. Set "Date From" to 01-Jan-2026 and "Date To" to 31-Mar-2026. 3. VERIFY: Only RH history entries within Jan-Mar 2026 are displayed. 4. VERIFY: Entries outside the range are hidden. 5. Change the date range and VERIFY results update accordingly.
A5: RH-039 | B5: History Tab | C5: Sort history ascending/descending | D5: Low | E5: 1. View component history 2. Toggle sort order 3. Verify order changes | F5: Sort: Asc → Desc | G5: History entries sorted by date ascending then descending | M5: HOW TO TEST: 1. In RH History tab, select a component with multiple entries. 2. Click the date column header to sort ascending. 3. VERIFY: Oldest entries appear first. 4. Click again to sort descending. 5. VERIFY: Newest entries appear first.
A6: RH-040 | B6: Update Dialog | C6: Update RH using "Set Total" mode | D6: High | E6: 1. Click update on component 2. Select "Set Total" mode 3. Enter absolute RH value 4. Save | F6: Set Total: 15000 | G6: RH set to exact value 15000. Delta calculated automatically. | M6: HOW TO TEST: 1. Navigate to PMS > Running Hours and select a vessel. 2. Click the update/edit button on a component. 3. In the update dialog, select "Set Total" mode. 4. Enter 15000 as the total RH value. 5. VERIFY: The delta (difference from current) is auto-calculated. 6. Click Save. 7. VERIFY: The component now shows 15000 as its RH value. 8. VERIFY: The history log shows the update with the delta.
A7: RH-041 | B7: Update Dialog | C7: Update RH using "Add Delta" mode | D7: High | E7: 1. Click update on component 2. Select "Add Delta" mode 3. Enter hours to add 4. Save | F7: Add Delta: 24 | G7: RH incremented by 24. New total = previous + 24. | M7: HOW TO TEST: 1. Note the current RH for a component (e.g., 10000). 2. Click the update button and select "Add Delta" mode. 3. Enter 24 hours. 4. Click Save. 5. VERIFY: The new RH total is previous + 24 (e.g., 10024). 6. VERIFY: The history log shows "+24" delta entry.
A8: RH-042 | B8: Meter Replaced | C8: Update RH with Meter Replaced toggle | D8: High | E8: 1. Click update 2. Toggle "Meter Replaced" on 3. Enter Old Meter Final, New Meter Start 4. Enter Renewal Reason 5. Save | F8: Old: 50000, New: 0 Reason: "Counter replacement" | G8: Meter replacement recorded. History shows reset event. RH continues from new start. | M8: HOW TO TEST: 1. Click the update button on a component. 2. Toggle "Meter Replaced" on. 3. VERIFY: Additional fields appear: Old Meter Final Reading, New Meter Start Reading, Renewal Reason. 4. Enter Old Meter Final: 50000, New Meter Start: 0. 5. Enter Reason: "Counter replacement". 6. Save. 7. VERIFY: History shows a meter reset event. 8. VERIFY: RH continues tracking from 0 (new meter start).
A9: RH-043 | B9: Meter Replaced | C9: Meter Replaced requires confirmation | D9: Medium | E9: 1. Toggle Meter Replaced 2. Verify confirmation dialog appears 3. Must enter Old Final and New Start | F9: N/A | G9: Confirmation dialog requires all meter replacement fields before saving. | M9: HOW TO TEST: 1. Open the RH update dialog. 2. Toggle "Meter Replaced" on. 3. Try to save without filling Old Final and New Start. 4. VERIFY: Validation prevents saving — all meter replacement fields are required. 5. Fill in the required fields. 6. VERIFY: A confirmation dialog appears before the meter replacement is recorded.
A10: RH-044 | B10: Zero RH | C10: Set RH to zero requires Renewal Action Type | D10: High | E10: 1. Update RH 2. Set value to 0 3. Verify special confirmation 4. Select Renewal Action Type | F10: New RH: 0 | G10: Zero RH confirmation dialog. Must select Renewal Action (Overhaul/Replacement) before save. | M10: HOW TO TEST: 1. Open the RH update dialog for a component with non-zero RH. 2. Set the value to 0. 3. VERIFY: A special confirmation dialog appears warning about setting RH to zero. 4. VERIFY: The dialog requires selecting a Renewal Action Type (Overhaul or Replacement). 5. Select "Overhaul" and confirm. 6. VERIFY: RH is set to 0 and the action type is logged.
A11: RH-045 | B11: Child RH | C11: Update parent RH cascades to children | D11: High | E11: 1. Update RH on parent component 2. Verify Child RH Popup appears 3. Review sub-component updates 4. Confirm | F11: Parent: Main Engine, Children: Turbo, Pump | G11: Child RH Popup shows sub-components. Can edit child values. Cascade applied on confirm. | M11: HOW TO TEST: 1. Navigate to Running Hours. 2. Find a parent component with child components (e.g., Main Engine with Turbo and Pump). 3. Update the parent RH (e.g., add 24 hours). 4. VERIFY: A "Child RH Popup" appears showing all sub-components. 5. VERIFY: Each child component shows the proposed cascaded RH update. 6. Optionally modify a child value independently. 7. Confirm and VERIFY all children are updated accordingly.
A12: RH-046 | B12: Child RH | C12: Edit child RH independently in popup | D12: Medium | E12: 1. Update parent RH 2. In Child Popup, modify one child value independently 3. Save | F12: Child override: different delta | G12: Child component gets custom RH value instead of cascaded value. | M12: HOW TO TEST: 1. Update a parent component RH. 2. In the Child RH Popup, locate a specific child component. 3. Change its delta value to a different number than the parent. 4. Save. 5. VERIFY: That child gets the custom value while others get the cascaded value. 6. Check the RH list and VERIFY the child shows the custom value.
A13: RH-047 | B13: Utilization Period | C13: Switch utilization period selector | D13: Medium | E13: 1. Navigate to Running Hours 2. Change period: Weekly → Monthly → Quarterly → Yearly 3. Verify rate recalculation | F13: All four periods | G13: Utilization rate recalculated for each period. Colors update based on thresholds. | M13: HOW TO TEST: 1. Navigate to PMS > Running Hours and select a vessel. 2. Find the utilization period selector (dropdown or buttons). 3. Switch to "Weekly" and note the utilization rate. 4. Switch to "Monthly" and VERIFY the rate changes. 5. Switch to "Quarterly" and "Yearly" and VERIFY each recalculates. 6. VERIFY: Color coding updates (green/amber/red) based on thresholds for each period.
... A21: RH-055 | B21: Export | C21: Export main RH list to CSV | D21: Medium | E21: 1. Navigate to RH dashboard 2. Apply filters 3. Click Export 4. Download | F21: N/A | G21: CSV with all visible components, RH values, and utilization rates. | M21: HOW TO TEST: 1. Navigate to Running Hours and apply any active filters. 2. Click the "Export" button on the main list view. 3. VERIFY: A CSV file downloads. 4. Open it and VERIFY it contains: Component, Current RH, Utilization %, Last Updated. 5. VERIFY: Only the filtered (visible) components are included.

Sheet Spares Additional
A1: Test Case ID | B1: Module/Section | C1: Test Scenario | D1: Priority | E1: Test Steps | F1: Test Data | G1: Expected Result | H1: Actual Result | I1: Pass/Fail | J1: Comments/Issues | K1: Tester Name | L1: Test Date | M1: How to Test
A2: SP-041 | B2: By Location Tab | C2: View spares grouped by storage location | D2: Medium | E2: 1. Navigate to Spares 2. Click "By Location" tab 3. Verify grouping | F2: N/A | G2: Spares displayed grouped by physical storage location (Engine Room, Deck Store, etc.) | M2: HOW TO TEST: 1. Navigate to PMS > Spares and select a vessel. 2. Click the "By Location" tab. 3. VERIFY: Spares are grouped by their physical storage location. 4. VERIFY: Each location group shows the location name and the spares stored there. 5. VERIFY: Quantities are shown per spare within each location.
A3: SP-042 | B3: By Location Tab | C3: Location A and B quantities displayed | D3: Medium | E3: 1. View By Location tab 2. Check spare with dual locations 3. Verify qty shown per location | F3: Spare with stock in both locations | G3: Shows Location A qty and Location B qty separately. Total ROB = sum. | M3: HOW TO TEST: 1. In the By Location tab, find a spare with stock in both Location A and Location B. 2. VERIFY: Location A quantity is shown separately. 3. VERIFY: Location B quantity is shown separately. 4. VERIFY: Total ROB = Location A qty + Location B qty. 5. VERIFY: Both location values match what is shown in the main Spares list.
A4: SP-043 | B4: History Tab | C4: View spare transaction ledger | D4: High | E4: 1. Navigate to Spares > History tab 2. Select a spare 3. Verify ledger entries | F4: N/A | G4: Ledger shows all transactions: Date, Type (Consume/Receive/Transfer/Adjust), Qty, Running Balance | M4: HOW TO TEST: 1. Navigate to PMS > Spares and click the "History" tab. 2. Search for and select a spare part. 3. VERIFY: A ledger/transaction history is displayed. 4. VERIFY: Each entry shows: Date, Transaction Type, Quantity, Running Balance. 5. VERIFY: Transaction types include Consume, Receive, Transfer, and Adjust. 6. VERIFY: The running balance is mathematically correct for each entry.
A5: SP-044 | B5: History Tab | C5: Filter history by event type | D5: Medium | E5: 1. View spare history 2. Filter by event type (Consume only) 3. Verify filtered results | F5: Filter: Consume | G5: Only consume transactions displayed | M5: HOW TO TEST: 1. In Spares History, select a spare with multiple transaction types. 2. Apply the event type filter and select "Consume" only. 3. VERIFY: Only consume transactions are displayed. 4. VERIFY: Receive, Transfer, and Adjust entries are hidden. 5. Change filter to "Receive" and VERIFY only receive entries show.
A6: SP-045 | B6: History Tab | C6: Filter history by date range | D6: Medium | E6: 1. View spare history 2. Set Date From and Date To 3. Verify filtered results | F6: From: 01-Jan, To: 31-Mar | G6: Only transactions within date range displayed | M6: HOW TO TEST: 1. In Spares History, select a spare. 2. Set Date From: 01-Jan-2026, Date To: 31-Mar-2026. 3. VERIFY: Only transactions within Jan-Mar 2026 are shown. 4. VERIFY: Transactions outside this range are hidden.
A7: SP-046 | B7: Add Spare | C7: Add spare with Maker List integration | D7: Medium | E7: 1. Click Add Spare 2. In Maker field, search from Maker List 3. Select maker 4. Save | F7: Maker: From fleet maker database | G7: Maker validated against central fleet maker database. Spare saved with linked maker. | M7: HOW TO TEST: 1. Navigate to Spares and click "Add Spare". 2. In the Maker field, start typing a maker name. 3. VERIFY: A dropdown or search suggests makers from the fleet-wide maker database. 4. Select a maker from the suggestions. 5. Complete other required fields and save. 6. VERIFY: The spare is saved with the selected maker linked.
A8: SP-047 | B8: Add Spare | C8: Add spare with IHM status | D8: Medium | E8: 1. Click Add Spare 2. Toggle IHM status on 3. Set hazard category 4. Save | F8: IHM: Yes, Category: Table A | G8: Spare created with IHM flag. Visible in IHM module. | M8: HOW TO TEST: 1. Click "Add Spare" in the Spares module. 2. Toggle the IHM (Inventory of Hazardous Materials) status to "Yes". 3. VERIFY: Additional fields appear (Hazard Category, etc.). 4. Select "Table A" as the hazard category. 5. Fill in other fields and save. 6. VERIFY: The spare shows an IHM indicator in the spares list. 7. Navigate to the IHM module and VERIFY the spare appears there.
A9: SP-048 | B9: Transaction | C9: Consume/Receive selection step | D9: High | E9: 1. Click transaction button on spare 2. Verify selection dialog (Consume or Receive) 3. Select one | F9: N/A | G9: Selection step shows Consume vs Receive options. Correct form opens after selection. | M9: HOW TO TEST: 1. Navigate to Spares and find a spare with stock. 2. Click the transaction button (e.g., +/- icon or "Transaction" button). 3. VERIFY: A selection dialog appears with options: "Consume" and "Receive". 4. Select "Consume" and VERIFY the consume form opens. 5. Cancel, click transaction again, select "Receive" and VERIFY the receive form opens.
A10: SP-049 | B10: Transaction | C10: Consume spare from specific location | D10: High | E10: 1. Select Consume 2. Choose Location A or B 3. Enter quantity 4. Save | F10: Location: A, Qty: 3 | G10: Stock decremented from selected location only. Other location unchanged. | M10: HOW TO TEST: 1. Note the current stock at Location A and Location B for a spare. 2. Initiate a Consume transaction. 3. Select "Location A" as the source. 4. Enter quantity: 3. 5. Save. 6. VERIFY: Location A stock decreased by 3. 7. VERIFY: Location B stock is unchanged. 8. VERIFY: Total ROB decreased by 3.
A11: SP-050 | B11: Transaction | C11: Receive spare to specific location | D11: High | E11: 1. Select Receive 2. Choose Location 3. Enter qty, date, optional WO/Supplier/Remarks 4. Save | F11: Location: B, Qty: 10, Supplier: "Marine Parts" | G11: Stock incremented at selected location. Transaction logged with receipt details. | M11: HOW TO TEST: 1. Initiate a Receive transaction for a spare. 2. Select "Location B". 3. Enter qty: 10, date: today, supplier: "Marine Parts". 4. Save. 5. VERIFY: Location B stock increased by 10. 6. VERIFY: Transaction logged with supplier name and receipt date. 7. Check History tab to VERIFY the receive entry is recorded.
A12: SP-051 | B12: Transaction | C12: Adjust stock quantity | D12: Medium | E12: 1. Open Adjust modal 2. Set new quantity for location 3. Enter reason 4. Save | F12: Adjust: 10 → 8, Reason: "Physical count" | G12: Stock adjusted. Transaction logged as "Adjust" with reason. | M12: HOW TO TEST: 1. Open the stock adjustment option for a spare. 2. Change the quantity from 10 to 8. 3. Enter reason: "Physical count". 4. Save. 5. VERIFY: Stock is now 8. 6. Check History and VERIFY an "Adjust" transaction is logged with the reason.
A13: SP-052 | B13: Location Management | C13: Rename Location A/B for a spare | D13: Low | E13: 1. Open spare details 2. Click location settings 3. Rename "Location A" to "Engine Room Store" 4. Save | F13: New name: "Engine Room Store" | G13: Location label renamed. Displayed with custom name across spare views. | M13: HOW TO TEST: 1. Open a spare's details. 2. Find the location settings or edit option. 3. Rename "Location A" to "Engine Room Store". 4. Save. 5. VERIFY: The custom name appears everywhere the location is referenced. 6. VERIFY: Transactions now show "Engine Room Store" instead of "Location A".
... A26: SP-065 | B26: Edit Spare | C26: Edit spare technical details | D26: Medium | E26: 1. Open spare 2. Click Edit 3. Modify technical details (Manual Reference) 4. Save | F26: Manual: "Service Manual Rev 3" | G26: Technical details updated and saved. | M26: HOW TO TEST: 1. Open a spare's details. 2. Click "Edit". 3. Modify the Manual Reference field to "Service Manual Rev 3". 4. Save. 5. VERIFY: The updated manual reference is displayed in the spare details. 6. VERIFY: The change is persisted after page refresh.

Sheet Stores Additional
A1: Test Case ID | B1: Module/Section | C1: Test Scenario | D1: Priority | E1: Test Steps | F1: Test Data | G1: Expected Result | H1: Actual Result | I1: Pass/Fail | J1: Comments/Issues | K1: Tester Name | L1: Test Date | M1: How to Test
A2: ST-026 | B2: Category Tabs | C2: Navigate between Stores/Lubes/Chemicals/Others tabs | D2: High | E2: 1. Navigate to Stores 2. Click each category tab 3. Verify data changes per tab | F2: All 4 tabs | G2: Each tab shows items specific to that category. Counts update per tab. | M2: HOW TO TEST: 1. Navigate to PMS > Stores and select a vessel. 2. Click the "Stores" tab. VERIFY items specific to general stores are shown. 3. Click "Lubes" tab. VERIFY only lubricants/oils are displayed. 4. Click "Chemicals" tab. VERIFY only chemicals are shown (with safety fields). 5. Click "Others" tab. VERIFY miscellaneous items are displayed. 6. VERIFY: Item counts update correctly for each tab.
A3: ST-027 | B3: View Modes | C3: Switch between Inventory/Location/History sub-views | D3: Medium | E3: 1. Select a category tab 2. Switch between Inventory, Location, and History sub-views 3. Verify each view | F3: N/A | G3: Inventory: list view. Location: grouped by storage. History: transaction ledger. | M3: HOW TO TEST: 1. Navigate to Stores and select any category tab. 2. Click "Inventory" sub-view. VERIFY: List of items with quantities. 3. Click "Location" sub-view. VERIFY: Items grouped by storage location. 4. Click "History" sub-view. VERIFY: Transaction ledger with dates and types. 5. VERIFY: Each sub-view loads correctly without errors.
A4: ST-028 | B4: Chemicals | C4: Add chemical item with safety fields | D4: High | E4: 1. Click Chemicals tab 2. Add new item 3. Fill: UN Number, Flash Point, Storage Temp, PPE, Disposal 4. Save | F4: UN: 1203 Flash Point: 23°C PPE: Gloves, Goggles | G4: Chemical item created with all safety fields. SDS reference linkable. | M4: HOW TO TEST: 1. Navigate to Stores > Chemicals tab. 2. Click "Add Item". 3. Fill in the item name. 4. Enter UN Number: 1203, Flash Point: 23°C. 5. Set Storage Temperature range. 6. Select PPE: Gloves, Goggles. 7. Enter Disposal Instructions. 8. Save. 9. VERIFY: Chemical item is created with all safety data visible. 10. VERIFY: SDS (Safety Data Sheet) reference field is available.
A5: ST-029 | B5: Chemicals | C5: Chemical expiry date tracking | D5: High | E5: 1. Navigate to Chemicals 2. Check items with expiry dates 3. Verify visual indicators | F5: Item with expired date | G5: Expired items show red indicator. Near-expiry (30 days) show amber warning. | M5: HOW TO TEST: 1. Navigate to Stores > Chemicals. 2. Find an item with an expiry date in the past. 3. VERIFY: A red indicator or badge shows "Expired". 4. Find an item expiring within 30 days. 5. VERIFY: An amber/yellow warning indicator is shown. 6. VERIFY: Items with future expiry dates show no warning.
A6: ST-030 | B6: Chemicals | C6: SDS (Safety Data Sheet) reference | D6: Medium | E6: 1. Open chemical item 2. Check SDS field 3. Verify link/download if present | F6: N/A | G6: SDS reference field available. Can link to or upload safety data sheet. | M6: HOW TO TEST: 1. Open a chemical item's details. 2. Locate the SDS (Safety Data Sheet) field. 3. VERIFY: The field exists and can hold a reference or file. 4. If an SDS is uploaded, VERIFY it can be downloaded or viewed. 5. If no SDS, VERIFY the field can accept an upload.
A7: ST-031 | B7: Chemicals | C7: Storage temperature min/max | D7: Medium | E7: 1. Add/Edit chemical 2. Set Storage Temp Min and Max 3. Save | F7: Min: 5°C, Max: 25°C | G7: Storage temperature range saved and displayed on chemical details. | M7: HOW TO TEST: 1. Edit a chemical item. 2. Set Storage Temp Min: 5°C, Max: 25°C. 3. Save. 4. VERIFY: The temperature range is saved and visible in the item details. 5. VERIFY: The values persist after page refresh.
A8: ST-032 | B8: Chemicals | C8: Disposal instructions field | D8: Low | E8: 1. Add/Edit chemical 2. Enter disposal instructions 3. Save | F8: Disposal: "Return to shore facility" | G8: Disposal instructions saved and visible on item details. | M8: HOW TO TEST: 1. Edit a chemical item. 2. Enter disposal instructions: "Return to shore facility". 3. Save. 4. VERIFY: Disposal instructions are displayed in the item details. 5. VERIFY: The text is complete and untruncated.
A9: ST-033 | B9: Lubes | C9: View Lubes tab with oil tracking | D9: Medium | E9: 1. Click Lubes tab 2. Verify lube-specific fields displayed 3. Check stock levels | F9: N/A | G9: Lubes tab shows oil types, grades, consumption rates, and quality tracking. | M9: HOW TO TEST: 1. Navigate to Stores > Lubes tab. 2. VERIFY: Lube oil items are listed with relevant fields. 3. VERIFY: Fields may include oil type, grade, viscosity, consumption rate. 4. VERIFY: Stock levels (ROB) are displayed for each lube item.
A10: ST-034 | B10: IHM Management | C10: Set IHM Presence on store item | D10: Medium | E10: 1. Edit store item 2. Toggle IHM Presence on 3. Select Evidence Type 4. Save | F10: IHM: Present Evidence: SDoC | G10: IHM data saved. Presence marked. Evidence type set (MD/SDoC/Test). | M10: HOW TO TEST: 1. Edit a store item. 2. Toggle "IHM Presence" to on/yes. 3. VERIFY: Evidence Type field appears. 4. Select "SDoC" (Supplier Declaration of Conformity). 5. Save. 6. VERIFY: IHM Presence is marked on the item. 7. VERIFY: The item appears in IHM-related reports.
A11: ST-035 | B11: IMPA Code | C11: Enter IMPA code for store item | D11: Low | E11: 1. Add/Edit store item 2. Enter IMPA code 3. Save | F11: IMPA: 370101 | G11: IMPA code saved. Searchable by IMPA code in search bar. | M11: HOW TO TEST: 1. Edit a store item. 2. Enter IMPA code: 370101. 3. Save. 4. VERIFY: The IMPA code is saved and visible in item details. 5. Search for "370101" in the stores search bar. 6. VERIFY: The item appears in search results when searching by IMPA code.
A12: ST-036 | B12: History View | C12: Filter history by event type | D12: Medium | E12: 1. Navigate to History sub-view 2. Filter by Event Type (Receive/Consume/Edit/Transfer) 3. Verify filtered | F12: Filter: Receive | G12: Only Receive events shown in history | M12: HOW TO TEST: 1. Navigate to Stores > History sub-view. 2. Select an item and apply Event Type filter: "Receive". 3. VERIFY: Only Receive transactions are shown. 4. Switch to "Consume" and VERIFY only consume entries appear.
A13: ST-037 | B13: History View | C13: Filter history by date range | D13: Medium | E13: 1. Navigate to History 2. Set date range 3. Verify filtered results | F13: From: 01-Jan, To: 28-Feb | G13: Only transactions within date range displayed | M13: HOW TO TEST: 1. In Stores History, set Date From: 01-Jan-2026, Date To: 28-Feb-2026. 2. VERIFY: Only transactions within Jan-Feb 2026 are displayed. 3. VERIFY: Entries outside this range are hidden.
... A26: ST-050 | B26: Edge Cases | C26: Transfer stock between locations | D26: Medium | E26: 1. Open store item 2. Transfer qty from Location A to B 3. Save | F26: Transfer: 5 units A→B | G26: Location A decremented, Location B incremented. Transfer transaction logged. | M26: HOW TO TEST: 1. Note current stock at Location A and B for a store item. 2. Initiate a transfer: From Location A, To Location B, Qty: 5. 3. Save. 4. VERIFY: Location A decreased by 5, Location B increased by 5. 5. VERIFY: Total ROB unchanged. 6. VERIFY: History shows a "Transfer" transaction.

Sheet Reports Additional
A1: Test Case ID | B1: Module/Section | C1: Test Scenario | D1: Priority | E1: Test Steps | F1: Test Data | G1: Expected Result | H1: Actual Result | I1: Pass/Fail | J1: Comments/Issues | K1: Tester Name | L1: Test Date | M1: How to Test
A2: RPT-036 | B2: Module Landing | C2: View Reports landing page with 9 category cards | D2: High | E2: 1. Navigate to Reports 2. Verify 9 report category cards displayed 3. Check each card title and description | F2: N/A | G2: Grid shows: Maintenance Planner, Maintenance & WO, Running Hours, Spares, Stores, IHM, Change Requests, Critical Equipment, LSA/FFA | M2: HOW TO TEST: 1. Navigate to PMS > Reports from the sidebar. 2. VERIFY: The landing page displays a grid of 9 report category cards. 3. VERIFY: Card titles include: Maintenance Planner, Maintenance & Work Orders, Running Hours, Spares, Stores, IHM, Change Requests, Critical Equipment, LSA/FFA. 4. VERIFY: Each card has a title, icon, and brief description. 5. VERIFY: Cards are clickable and navigate to their respective sub-pages.
A3: RPT-037 | B3: Module Landing | C3: Search reports by keyword | D3: Medium | E3: 1. On Reports landing 2. Type keyword in search bar 3. Verify cards filtered | F3: Search: "spares" | G3: Category cards filter to show matching report categories | M3: HOW TO TEST: 1. On the Reports landing page, locate the search bar. 2. Type "spares". 3. VERIFY: Only category cards related to spares are visible. 4. VERIFY: Non-matching cards are hidden. 5. Clear search and VERIFY all 9 cards reappear.
A4: RPT-038 | B4: Module Landing | C4: Schedule Reports button (Sail Admin) | D4: High | E4: 1. Login as Sail Admin 2. Navigate to Reports 3. Verify "Schedule Reports" button visible | F4: Role: Sail Admin | G4: Schedule Reports button visible in header for Sail Admin only | M4: HOW TO TEST: 1. Log in as a user with "Sail Admin" role. 2. Navigate to PMS > Reports. 3. VERIFY: A "Schedule Reports" button is visible in the header area. 4. Click it and VERIFY it opens a scheduling interface.
A5: RPT-039 | B5: Module Landing | C5: Export Queue button (Sail Admin) | D5: Medium | E5: 1. Login as Sail Admin 2. Navigate to Reports 3. Verify "Export Queue" button visible | F5: Role: Sail Admin | G5: Export Queue button visible in header for Sail Admin only | M5: HOW TO TEST: 1. Log in as Sail Admin. 2. Navigate to PMS > Reports. 3. VERIFY: An "Export Queue" button is visible. 4. Click it and VERIFY it shows queued/pending export jobs.
A6: RPT-040 | B6: Module Landing | C6: Schedule/Export buttons hidden for non-Sail Admin | D6: High | E6: 1. Login as non-Sail Admin 2. Navigate to Reports 3. Check header buttons | F6: Role: Vessel User | G6: Schedule Reports and Export Queue buttons not visible | M6: HOW TO TEST: 1. Log in as a non-Sail Admin user (e.g., Vessel User, Viewer). 2. Navigate to PMS > Reports. 3. VERIFY: "Schedule Reports" button is NOT visible. 4. VERIFY: "Export Queue" button is NOT visible. 5. VERIFY: Standard report access is still available.
A7: RPT-041 | B7: Module Landing | C7: Clear All filters button | D7: Low | E7: 1. Apply vessel filter and date range 2. Click "Clear" button 3. Verify all filters reset | F7: N/A | G7: All filters reset. Full unfiltered category list displayed. | M7: HOW TO TEST: 1. On the Reports landing page, apply a vessel filter and date range. 2. Click the "Clear" or "Reset" button. 3. VERIFY: All filters are cleared. 4. VERIFY: The full unfiltered view is restored.
A8: RPT-042 | B8: Module Landing | C8: Click category card navigates to sub-page | D8: High | E8: 1. Click "Maintenance & Work Orders" card 2. Verify sub-page loads 3. Click Back arrow 4. Verify return to landing | F8: N/A | G8: Sub-page opens with category-specific reports. Back arrow returns to landing. | M8: HOW TO TEST: 1. On Reports landing, click the "Maintenance & Work Orders" card. 2. VERIFY: The sub-page loads showing maintenance-specific reports. 3. Click the Back arrow or breadcrumb. 4. VERIFY: You return to the Reports landing page with all 9 cards.
A9: RPT-043 | B9: Module Landing | C9: Report count badge on category cards | D9: Low | E9: 1. View category cards 2. Check report count badges 3. Verify counts match actual sub-reports | F9: N/A | G9: Each card shows accurate report count (e.g., "10 reports" for Maintenance) | M9: HOW TO TEST: 1. View the Reports landing page. 2. Check each category card for a report count badge. 3. Click into a category and count the sub-reports. 4. VERIFY: The badge count matches the actual number of sub-reports.
A10: RPT-044 | B10: Maintenance Planner | C10: View Maintenance Planner summary cards | D10: High | E10: 1. Click Maintenance Planner category 2. Verify summary cards displayed | F10: N/A | G10: Cards show: Total Jobs, Total Man-Hours, Status Breakdown (Overdue/Grace/Due Soon/Future), Workload by Rank | M10: HOW TO TEST: 1. Navigate to Reports > Maintenance Planner. 2. Select a vessel. 3. VERIFY: Summary cards display at the top: Total Jobs, Total Man-Hours, Status Breakdown. 4. VERIFY: Status breakdown shows counts for Overdue, Grace, Due Soon, and Future. 5. VERIFY: Workload by Rank shows hours distributed across ranks.
A11: RPT-045 | B11: Maintenance Planner | C11: Interactive job table with pagination | D11: High | E11: 1. Open Maintenance Planner 2. Scroll through job table 3. Navigate pages | F11: N/A | G11: Paginated table with sortable columns. Status badges and spare availability icons per row. | M11: HOW TO TEST: 1. Open the Maintenance Planner. 2. VERIFY: A table displays with job rows. 3. VERIFY: Columns are sortable (click headers). 4. VERIFY: Each row shows status badges (Overdue/Due/Future) and spare availability icons. 5. Navigate through pagination controls. 6. VERIFY: Pages load correctly with different data sets.
A12: RPT-046 | B12: Maintenance Planner | C12: Filter by Job Type (Calendar/RH/Both) | D12: Medium | E12: 1. Open Planner 2. Select "Calendar" jobs only 3. Verify filtered 4. Select "RH" only 5. Select "Both" | F12: Filter: Calendar → RH → Both | G12: Table filters to show only calendar-based, RH-based, or all jobs | M12: HOW TO TEST: 1. Open Maintenance Planner. 2. Find the Job Type filter (Calendar/RH/Both). 3. Select "Calendar". VERIFY: Only calendar-based jobs shown. 4. Select "RH". VERIFY: Only running-hours-based jobs shown. 5. Select "Both". VERIFY: All jobs from both types are shown.
A13: RPT-047 | B13: Maintenance Planner | C13: Date window buttons (7d/30d/60d/90d) | D13: Medium | E13: 1. Open Planner 2. Click "7d" button 3. Verify jobs due within 7 days 4. Click "30d" etc. | F13: Window: 7, 30, 60, 90 days | G13: Table shows only jobs due within selected window period | M13: HOW TO TEST: 1. Open Maintenance Planner. 2. Click the "7d" button. VERIFY: Only jobs due within 7 days are shown. 3. Click "30d". VERIFY: Jobs due within 30 days are shown. 4. Click "60d" then "90d" and VERIFY each filters correctly. 5. VERIFY: Summary cards update to reflect the filtered count.
... A81: RPT-115 | B81: Compliance Reports | C81: Compliance report with no data | D81: Medium | E81: 1. Select vessel with no compliance data 2. Generate compliance report 3. Verify empty state | F81: Vessel with no certificates | G81: Report shows "No data available" message. No error thrown. | M81: HOW TO TEST: 1. Select a vessel that has no compliance/certificate data. 2. Try to generate a compliance report. 3. VERIFY: The report shows "No data available" or similar empty state. 4. VERIFY: No error or crash occurs.

Sheet Dashboard Additional
A1: Test Case ID | B1: Module/Section | C1: Test Scenario | D1: Priority | E1: Test Steps | F1: Test Data | G1: Expected Result | H1: Actual Result | I1: Pass/Fail | J1: Comments/Issues | K1: Tester Name | L1: Test Date | M1: How to Test
A2: DASH-053 | B2: Fleet Benchmarking | C2: View fleet comparison table on Management tab | D2: High | E2: 1. Navigate to Dashboard 2. Click Management tab 3. Verify fleet table displayed | F2: N/A | G2: Fleet table shows all vessels with columns: Name, Overdue %, Outstanding %, Compliance %, Low Stock, Overdue Count | M2: HOW TO TEST: 1. Navigate to PMS > Dashboard. 2. Click the "Management" tab. 3. VERIFY: A fleet comparison table is displayed. 4. VERIFY: Columns include Vessel Name, Overdue %, Outstanding %, Compliance %, Low Stock count, Overdue Count. 5. VERIFY: All vessels in the fleet are listed.
A3: DASH-054 | B3: Fleet Benchmarking | C3: Sort fleet table by Overdue % | D3: Medium | E3: 1. View Management tab 2. Click "Overdue %" column header 3. Verify sorting | F3: N/A | G3: Vessels sorted by overdue percentage ascending/descending | M3: HOW TO TEST: 1. On the Management tab, click the "Overdue %" column header. 2. VERIFY: Vessels sort by overdue percentage ascending. 3. Click again. VERIFY: Sort order reverses to descending.
A4: DASH-055 | B4: Fleet Benchmarking | C4: Click vessel name navigates to vessel dashboard | D4: High | E4: 1. In fleet table, click on a vessel name 2. Verify context switches 3. Dashboard shows vessel data | F4: Click: "Alejandro" | G4: Dashboard switches to Alejandro vessel context. Overview tab shows vessel-specific data. | M4: HOW TO TEST: 1. On the Management tab fleet table, click on a vessel name (e.g., "Alejandro"). 2. VERIFY: The dashboard switches to the Overview tab for that vessel. 3. VERIFY: The vessel selector updates to show "Alejandro". 4. VERIFY: All KPIs and charts reflect Alejandro's data.
A5: DASH-056 | B5: Fleet Benchmarking | C5: Fleet status badges (Critical/At Risk/Good) | D5: Medium | E5: 1. View fleet table 2. Check status badges 3. Verify thresholds | F5: N/A | G5: Critical (>40% overdue), At Risk (20-40%), Good (<20%) badges correctly applied. | M5: HOW TO TEST: 1. View the fleet table on Management tab. 2. Check the status badge for each vessel. 3. VERIFY: Vessels with >40% overdue show "Critical" (red). 4. VERIFY: 20-40% overdue shows "At Risk" (amber). 5. VERIFY: <20% overdue shows "Good" (green).
A6: DASH-057 | B6: Fleet Benchmarking | C6: InlineBar charts in fleet table cells | D6: Low | E6: 1. View fleet table 2. Check bar charts in percentage cells | F6: N/A | G6: Color-coded inline bars (Green/Amber/Red) visualize percentage metrics per vessel. | M6: HOW TO TEST: 1. View the fleet comparison table. 2. Look at percentage cells for inline bar charts. 3. VERIFY: Bars are color-coded (green for good, amber for warning, red for critical). 4. VERIFY: Bar widths are proportional to the percentage values.
A7: DASH-058 | B7: KPI Interaction | C7: Click Overdue KPI navigates to Overdue WO list | D7: High | E7: 1. Click on "Overdue WOs" gauge tile 2. Verify navigation | F7: N/A | G7: Navigates to Work Orders page with Overdue tab pre-selected | M7: HOW TO TEST: 1. On the Dashboard Overview tab, click the "Overdue WOs" gauge/tile. 2. VERIFY: The page navigates to PMS > Work Orders. 3. VERIFY: The "Overdue" tab is pre-selected. 4. VERIFY: The WO list shows only overdue work orders.
A8: DASH-059 | B8: KPI Interaction | C8: Click Completion Rate KPI shows detail | D8: Medium | E8: 1. Click on "Completion Rate" gauge 2. Verify navigation or detail | F8: N/A | G8: Navigates to completed WO list or shows detail breakdown. | M8: HOW TO TEST: 1. Click the "Completion Rate" gauge on the Dashboard. 2. VERIFY: Either navigates to completed WOs or shows a detail breakdown. 3. VERIFY: The data reflects the completion rate shown on the gauge.
A9: DASH-060 | B9: KPI Interaction | C9: Outstanding Tasks trend comparison | D9: Medium | E9: 1. View Outstanding Tasks gauge 2. Check trend vs last month 3. Verify calculation | F9: N/A | G9: Shows month-over-month comparison: "↑5% from last month" or "↓3%" | M9: HOW TO TEST: 1. View the Outstanding Tasks gauge/tile on Dashboard. 2. Look for a trend indicator (arrow up/down with percentage). 3. VERIFY: The trend shows month-over-month comparison. 4. VERIFY: The direction (up/down) and percentage are logical.
A10: DASH-061 | B10: Charts | C10: Click WO Status donut segment filters WOs | D10: High | E10: 1. View WO Status Distribution chart 2. Click "Overdue" segment 3. Verify navigation | F10: Click: Overdue segment | G10: Navigates to Work Orders page filtered by Overdue status | M10: HOW TO TEST: 1. On Dashboard, find the WO Status Distribution donut chart. 2. Click the "Overdue" segment. 3. VERIFY: Navigates to Work Orders page. 4. VERIFY: The Overdue tab or filter is pre-selected. 5. VERIFY: Only overdue WOs are displayed.
A11: DASH-062 | B11: Charts | C11: Click Spares Stock donut segment | D11: Medium | E11: 1. View Spares Stock chart 2. Click "Low Stock" segment 3. Verify navigation | F11: Click: Low Stock segment | G11: Navigates to Spares module filtered by low stock items | M11: HOW TO TEST: 1. Find the Spares Stock chart on Dashboard. 2. Click the "Low Stock" segment. 3. VERIFY: Navigates to the Spares module. 4. VERIFY: The low stock filter is applied. 5. VERIFY: Only low stock spares are displayed.
A12: DASH-063 | B12: Dot Matrix | C12: Cross-vessel dot matrix visualization | D12: Medium | E12: 1. View Dashboard (All Vessel mode) 2. Check dot matrix grid 3. Verify color coding | F12: N/A | G12: Dot grid shows metrics across all vessels: Red (critical), Amber (warning), Grey (ok) dots | M12: HOW TO TEST: 1. On Dashboard, switch to All Vessels or Management view. 2. Look for the dot matrix visualization. 3. VERIFY: Grid shows one dot per vessel/metric combination. 4. VERIFY: Red = critical, Amber = warning, Grey/Green = OK. 5. VERIFY: Hovering a dot shows vessel name and metric value.
A13: DASH-064 | B13: Bulk Approval | C13: Trigger Bulk Approve from Dashboard | D13: High | E13: 1. View Dashboard pending approval section 2. Click "Bulk Approve" button 3. Verify modal opens | F13: Must have pending WOs | G13: BulkApproveModal opens from Dashboard. Lists all pending approval WOs. | M13: HOW TO TEST: 1. On Dashboard, find the pending approval section or tile. 2. Click the "Bulk Approve" button. 3. VERIFY: The Bulk Approve modal opens. 4. VERIFY: All pending WOs are listed with checkboxes. 5. VERIFY: You can select and approve from this modal.
