Workbook

Sheet Dashboard
A1: SAIL PMS | IMPLEMENTATION PROGRESS | U1: WK activity status | V1: Count | X1: Critical category | Y1: Received | Z1: Not received
U2: Yes | V2: =COUNTIF('Update Tracker'!$D$29:$D$41,"Yes") | X2: Components | Y2: =IF(ISNUMBER('Update Tracker'!B22),'Update Tracker'!B22,"") | Z2: =IF(ISNUMBER('Update Tracker'!D22),'Update Tracker'!D22,"")
A3: SAIL uploads data received from WK; remaining inputs and verification are with the Wah Kwong / WK Team. | U3: In Progress | V3: =COUNTIF('Update Tracker'!$D$29:$D$41,"In Progress") | X3: Spares | Y3: =IF(ISNUMBER('Update Tracker'!B23),'Update Tracker'!B23,"") | Z3: =IF(ISNUMBER('Update Tracker'!D23),'Update Tracker'!D23,"")
U4: N | V4: =COUNTIF('Update Tracker'!$D$29:$D$41,"N") | X4: Jobs | Y4: =IF(ISNUMBER('Update Tracker'!B24),'Update Tracker'!B24,"") | Z4: =IF(ISNUMBER('Update Tracker'!D24),'Update Tracker'!D24,"")
B5: Reporting period | C5: 46294 | G5: Last updated | H5: 46294 | U5: Not assessed | V5: =COUNTA('Update Tracker'!$A$29:$A$41)-COUNTA('Update Tracker'!$D$29:$D$41)
B6: Responsible person | C6: Jeevan | G6: Reporting to / audience | H6: Wah Kwong Team
B8: SAIL TEAM / DELIVERY | G8: WK TEAM / ACTIONS TO CONFIRM | J8: WK ACTIVITY STATUS
B10: Data received from WK (weighted) | C10: 30 / 30 / 30 / 10 | D10: =IF(AND(COUNT('Update Tracker'!AA7:AA10)=4,COUNT('Update Tracker'!B7:B10)=4,COUNTIF('Update Tracker'!AA7:AA10,">0")>0,SUMPRODUCT(--('Update Tracker'!B7:B10>=0))=4,SUMPRODUCT(--('Update Tracker'!B7:B10<='Update Tracker'!AA7:AA10))=4),(0.3*IF('Update Tracker'!AA7>0,'Update Tracker'!B7/'Update Tracker'!AA7,0)+0.3*IF('Update Tracker'!AA8>0,'Update Tracker'!B8/'Update Tracker'!AA8,0)+0.3*IF('Update Tracker'!AA9>0,'Update Tracker'!B9/'Update Tracker'!AA9,0)+0.1*IF('Update Tracker'!AA10>0,'Update Tracker'!B10/'Update Tracker'!AA10,0))/(0.3*--('Update Tracker'!AA7>0)+0.3*--('Update Tracker'!AA8>0)+0.3*--('Update Tracker'!AA9>0)+0.1*--('Update Tracker'!AA10>0)),"") | G10: Weighted progress | I10: =IF(COUNTIFS('Update Tracker'!$C$29:$C$41,">0",'Update Tracker'!$D$29:$D$41,"<>")=0,"",SUM('Update Tracker'!$E$29:$E$41)/SUM('Update Tracker'!$C$29:$C$41))
B12: Data loaded by SAIL (weighted) | C12: 30 / 30 / 30 / 10 | D12: =IF(AND(COUNT('Update Tracker'!AA7:AA10)=4,COUNT('Update Tracker'!B7:B10)=4,COUNTIF('Update Tracker'!AA7:AA10,">0")>0,SUMPRODUCT(--('Update Tracker'!B7:B10>=0))=4,SUMPRODUCT(--('Update Tracker'!B7:B10<='Update Tracker'!AA7:AA10))=4,COUNT('Update Tracker'!C7:C10)=4,SUMPRODUCT(--('Update Tracker'!C7:C10>=0))=4,SUMPRODUCT(--('Update Tracker'!C7:C10<='Update Tracker'!B7:B10))=4),(0.3*IF('Update Tracker'!AA7>0,'Update Tracker'!C7/'Update Tracker'!AA7,0)+0.3*IF('Update Tracker'!AA8>0,'Update Tracker'!C8/'Update Tracker'!AA8,0)+0.3*IF('Update Tracker'!AA9>0,'Update Tracker'!C9/'Update Tracker'!AA9,0)+0.1*IF('Update Tracker'!AA10>0,'Update Tracker'!C10/'Update Tracker'!AA10,0))/(0.3*--('Update Tracker'!AA7>0)+0.3*--('Update Tracker'!AA8>0)+0.3*--('Update Tracker'!AA9>0)+0.1*--('Update Tracker'!AA10>0)),"") | G12: Completed (Yes) | I12: =COUNTIF('Update Tracker'!$D$29:$D$41,"Yes")
B14: Components missing jobs | C14: Components affected | D14: =IF(ISNUMBER('Update Tracker'!B16),'Update Tracker'!B16,"") | G14: Open / incomplete | I14: =COUNTIF('Update Tracker'!$D$29:$D$41,"In Progress")+COUNTIF('Update Tracker'!$D$29:$D$41,"N")
B16: Components missing spares | C16: Components affected | D16: =IF(ISNUMBER('Update Tracker'!B17),'Update Tracker'!B17,"") | G16: Not assessed | I16: =COUNTA('Update Tracker'!$A$29:$A$41)-COUNTIF('Update Tracker'!$D$29:$D$41,"Yes")-COUNTIF('Update Tracker'!$D$29:$D$41,"In Progress")-COUNTIF('Update Tracker'!$D$29:$D$41,"N")
B18: Critical data received | C18: Received / estimated baseline | D18: =IF(AND(COUNT('Update Tracker'!AA22:AA24)=3,COUNT('Update Tracker'!B22:B24)=3,COUNTIF('Update Tracker'!AA22:AA24,">0")=3,SUMPRODUCT(--('Update Tracker'!B22:B24>=0))=3,SUMPRODUCT(--('Update Tracker'!B22:B24<='Update Tracker'!AA22:AA24))=3),SUM('Update Tracker'!B22:B24)/SUM('Update Tracker'!AA22:AA24),"") | G18: Score: Yes = 100% of weight; In Progress = 50%; N = 0%. Blank means not assessed.
B20: WOs generated till now | C20: Cumulative count | D20: =IF(ISNUMBER('Update Tracker'!B46),'Update Tracker'!B46,"") | G20: CLIENT STATUS / REMARKS | J20: CRITICAL ITEMS / RECEIPT
G21: SAIL Team scope: upload data received from WK. WK Team owns source-data verification, required inputs, reviews and decisions.
B22: RH machinery updated | C22: Vessel updated / created | D22: =IF(ISNUMBER('Update Tracker'!E56),'Update Tracker'!E56,"")
B23: WO status counts can overlap. Repeated cycles can produce several WOs per job; no jobs-based percentage.
B25: REPORTING NOTES / EDITABLE
B26: Key completed points | C26: Available Components, Jobs and Maker list data uploaded to SAIL PMS. WK verification remains pending.
B28: Pending points / next actions | C28: WK Team to provide spare data, confirm the Stores baseline, and complete the listed reviews and PMS decisions.
B30: Major risks / gaps | C30: Category baselines are rough estimates retained for weighted calculations; WK confirmation is needed before treating them as final.
B32: Other remarks | C32: SAIL responsibility is limited to uploading received data. All other inputs, verification and decisions remain with WK.
B34: Weighted data KPIs: Components 30%, Jobs 30%, Spares 30%, Stores 10%. Zero-baseline categories are excluded and active weights normalized; Maker list excluded.
B35: WORK ORDERS / RH MACHINERY SNAPSHOT
B36: Due | D36: =IF(ISNUMBER('Update Tracker'!B47),'Update Tracker'!B47,"") | G36: Overdue | I36: =IF(ISNUMBER('Update Tracker'!B48),'Update Tracker'!B48,"")
B37: Active | D37: =IF(ISNUMBER('Update Tracker'!B49),'Update Tracker'!B49,"") | G37: Pending approval | I37: =IF(ISNUMBER('Update Tracker'!B50),'Update Tracker'!B50,"") | J37: Critical chart compares received and pending WK quantities. SAIL loaded counts are shown in the tracker.
B38: Completed | D38: =IF(ISNUMBER('Update Tracker'!B51),'Update Tracker'!B51,"") | G38: RH machinery created | I38: =IF(ISNUMBER('Update Tracker'!B56),'Update Tracker'!B56,"")
B39: Vessel RH details updated | D39: =IF(ISNUMBER('Update Tracker'!C56),'Update Tracker'!C56,"") | G39: RH not updated | I39: =IF(ISNUMBER('Update Tracker'!D56),'Update Tracker'!D56,"")

Sheet Update Tracker
A1: SAIL PMS | UPDATE TRACKER
A3: Enter updates in yellow cells. Blue cells calculate automatically. Blank means unconfirmed; enter 0 only when confirmed.
A4: Quick update: record quantities received from WK and quantities loaded in SAIL separately; use the dropdowns for statuses.
A5: 01 /DATA UPLOAD
A6: Category | B6: Received from WK | C6: Loaded in SAIL | D6: Pending WK* | E6: Received % | F6: Loaded % | G6: Data Loading status | H6: Updated | I6: Target | J6: Notes | AA6: Estimated baseline (hidden)
A7: Components | B7: 1500 | C7: 1500 | D7: =IF(AND(ISNUMBER(AA7),ISNUMBER(B7),B7<=AA7),AA7-B7,"") | E7: =IF(AND(ISNUMBER(B7),ISNUMBER(AA7),AA7>0,B7<=AA7),B7/AA7,"") | F7: =IF(AND(ISNUMBER(C7),ISNUMBER(B7),ISNUMBER(AA7),AA7>0,C7<=B7,C7<=AA7),C7/AA7,"") | G7: Completed | H7: 46294 | I7: 46294 | J7: Data Verification Pending from WK | AA7: 1500
A8: Jobs | B8: 2000 | C8: 2000 | D8: =IF(AND(ISNUMBER(AA8),ISNUMBER(B8),B8<=AA8),AA8-B8,"") | E8: =IF(AND(ISNUMBER(B8),ISNUMBER(AA8),AA8>0,B8<=AA8),B8/AA8,"") | F8: =IF(AND(ISNUMBER(C8),ISNUMBER(B8),ISNUMBER(AA8),AA8>0,C8<=B8,C8<=AA8),C8/AA8,"") | G8: Completed | H8: 46294 | I8: 46294 | J8: Data Verification Pending from WK | AA8: 2000
A9: Spares | B9: 0 | C9: 0 | D9: =IF(AND(ISNUMBER(AA9),ISNUMBER(B9),B9<=AA9),AA9-B9,"") | E9: =IF(AND(ISNUMBER(B9),ISNUMBER(AA9),AA9>0,B9<=AA9),B9/AA9,"") | F9: =IF(AND(ISNUMBER(C9),ISNUMBER(B9),ISNUMBER(AA9),AA9>0,C9<=B9,C9<=AA9),C9/AA9,"") | G9: Pending Wah Kwong Input | H9: 46294 | I9: 46294 | J9: Awaiting for the data from Wah Kwong team | AA9: 18000
A10: Stores | B10: 0 | C10: 0 | D10: =IF(AND(ISNUMBER(AA10),ISNUMBER(B10),B10<=AA10),AA10-B10,"") | E10: =IF(AND(ISNUMBER(B10),ISNUMBER(AA10),AA10>0,B10<=AA10),B10/AA10,"") | F10: =IF(AND(ISNUMBER(C10),ISNUMBER(B10),ISNUMBER(AA10),AA10>0,C10<=B10,C10<=AA10),C10/AA10,"") | G10: Pending Wah Kwong Input | H10: 46294 | I10: 46294 | J10: Awaiting for the data from Wah Kwong team | AA10: 0
A11: Maker list | B11: 50 | C11: 50 | D11: =IF(AND(ISNUMBER(AA11),ISNUMBER(B11),B11<=AA11),AA11-B11,"") | E11: =IF(AND(ISNUMBER(B11),ISNUMBER(AA11),AA11>0,B11<=AA11),B11/AA11,"") | F11: =IF(AND(ISNUMBER(C11),ISNUMBER(B11),ISNUMBER(AA11),AA11>0,C11<=B11,C11<=AA11),C11/AA11,"") | G11: Completed | H11: 46294 | I11: 46294 | J11: Data Verification Pending from WK | AA11: 50
A12: Progress uses hidden rough-estimate baselines. Zero-baseline categories are excluded; Maker list is not weighted.
A14: 02 / DATA GAPS — JOBS & SPARES FOR COMPONENTS
A15: Gap | B15: Components | C15: Component IDs / names | G15: Status | H15: Target | I15: Updated | J15: Next step / notes
A16: Components missing jobs | B16: 200 | G16: Pending Wah Kwong Input | J16: Dates needs to updated by Wah Kwong Team
A17: Components missing spares | B17: 1500 | G17: Pending Wah Kwong Input | J17: Dates needs to updated by Wah Kwong Team
A18: List affected components by ID or name. A component with both gaps can appear in both rows, so do not add the counts.
A20: 03 / CRITICAL DATA — RECEIPT, SAIL LOADING & WK CHECK
A21: Critical item | B21: Received from WK | C21: Loaded in SAIL | D21: Pending WK* | E21: Pending SAIL upload | F21: Received % | G21: Loaded % | H21: WK status | I21: Updated | J21: Target | K21: Notes | AA21: Estimated critical baseline (hidden)
A22: Critical Components | B22: 50 | C22: 50 | D22: =IF(AND(ISNUMBER(AA22),ISNUMBER(B22),B22<=AA22),AA22-B22,"") | E22: =IF(AND(ISNUMBER(B22),ISNUMBER(C22),C22<=B22),B22-C22,"") | F22: =IF(AND(ISNUMBER(B22),ISNUMBER(AA22),AA22>0,B22<=AA22),B22/AA22,"") | G22: =IF(AND(ISNUMBER(C22),ISNUMBER(B22),ISNUMBER(AA22),AA22>0,C22<=B22,C22<=AA22),C22/AA22,"") | H22: Pending Review | K22: Dates needs to updated by Wah Kwong Team | AA22: 50
A23: Critical Spares | B23: 0 | D23: =IF(AND(ISNUMBER(AA23),ISNUMBER(B23),B23<=AA23),AA23-B23,"") | E23: =IF(AND(ISNUMBER(B23),ISNUMBER(C23),C23<=B23),B23-C23,"") | F23: =IF(AND(ISNUMBER(B23),ISNUMBER(AA23),AA23>0,B23<=AA23),B23/AA23,"") | G23: =IF(AND(ISNUMBER(C23),ISNUMBER(B23),ISNUMBER(AA23),AA23>0,C23<=B23,C23<=AA23),C23/AA23,"") | H23: Pending Wah Kwong Input | K23: Dates needs to updated by Wah Kwong Team | AA23: 50
A24: Critical Jobs | B24: 50 | C24: 50 | D24: =IF(AND(ISNUMBER(AA24),ISNUMBER(B24),B24<=AA24),AA24-B24,"") | E24: =IF(AND(ISNUMBER(B24),ISNUMBER(C24),C24<=B24),B24-C24,"") | F24: =IF(AND(ISNUMBER(B24),ISNUMBER(AA24),AA24>0,B24<=AA24),B24/AA24,"") | G24: =IF(AND(ISNUMBER(C24),ISNUMBER(B24),ISNUMBER(AA24),AA24>0,C24<=B24,C24<=AA24),C24/AA24,"") | H24: Pending Review | K24: Dates needs to updated by Wah Kwong Team | AA24: 50
A25: Track received and loaded separately. Leave unconfirmed quantities blank; hidden estimates support progress calculations only.
A27: 04 / WK TEAM INPUTS, REVIEWS & DECISIONS
A28: Work Element | B28: Description | C28: Weight % | D28: WK Completion | E28: Score | F28: Priority | G28: Target | H28: Completed | I28: Updated | J28: Notes / next action
A29: Equipment Register Creation | B29: All equipment listed | C29: 0.2 | D29: Yes | E29: =IF(OR(NOT(ISNUMBER(C29)),D29=""),"",C29*IF(D29="Yes",1,IF(D29="In Progress",0.5,IF(D29="N",0,"")))) | F29: High | J29: Pending input, review or decision from WK Team.
A30: Maker Manuals Collection | B30: OEM manuals uploaded | C30: 0.15 | D30: N | E30: =IF(OR(NOT(ISNUMBER(C30)),D30=""),"",C30*IF(D30="Yes",1,IF(D30="In Progress",0.5,IF(D30="N",0,"")))) | J30: Pending input, review or decision from WK Team.
A31: PMS Job Creation | B31: Maintenance tasks built | C31: 0.25 | D31: Yes | E31: =IF(OR(NOT(ISNUMBER(C31)),D31=""),"",C31*IF(D31="Yes",1,IF(D31="In Progress",0.5,IF(D31="N",0,""))))
A32: Interval Verification | B32: Intervals confirmed | C32: 0.1 | D32: N | E32: =IF(OR(NOT(ISNUMBER(C32)),D32=""),"",C32*IF(D32="Yes",1,IF(D32="In Progress",0.5,IF(D32="N",0,"")))) | J32: Pending input, review or decision from WK Team.
A33: Spare Parts Mapping | B33: Parts linked | C33: 0.1 | D33: N | E33: =IF(OR(NOT(ISNUMBER(C33)),D33=""),"",C33*IF(D33="Yes",1,IF(D33="In Progress",0.5,IF(D33="N",0,"")))) | J33: Pending input, review or decision from WK Team.
A34: Risk/Criticality Review | B34: Criticality completed | C34: 0.05 | D34: N | E34: =IF(OR(NOT(ISNUMBER(C34)),D34=""),"",C34*IF(D34="Yes",1,IF(D34="In Progress",0.5,IF(D34="N",0,"")))) | J34: Pending input, review or decision from WK Team.
A35: Class/Statutory Tasks | B35: Compliance tasks added | C35: 0.1 | D35: N | E35: =IF(OR(NOT(ISNUMBER(C35)),D35=""),"",C35*IF(D35="Yes",1,IF(D35="In Progress",0.5,IF(D35="N",0,"")))) | J35: Pending input, review or decision from WK Team.
A36: SMS Review | B36: Final verification | C36: 0.05 | D36: N | E36: =IF(OR(NOT(ISNUMBER(C36)),D36=""),"",C36*IF(D36="Yes",1,IF(D36="In Progress",0.5,IF(D36="N",0,"")))) | J36: Pending input, review or decision from WK Team.
A37: Supporting documentation | B37: Supporting records and documentation collected | E37: =IF(OR(NOT(ISNUMBER(C37)),D37=""),"",C37*IF(D37="Yes",1,IF(D37="In Progress",0.5,IF(D37="N",0,"")))) | J37: Pending input, review or decision from WK Team.
A38: Task procedures / instructions | B38: Task procedures and operating instructions | E38: =IF(OR(NOT(ISNUMBER(C38)),D38=""),"",C38*IF(D38="Yes",1,IF(D38="In Progress",0.5,IF(D38="N",0,"")))) | J38: Pending input, review or decision from WK Team.
A39: Spare parts source data | B39: Spare-parts reference data received | E39: =IF(OR(NOT(ISNUMBER(C39)),D39=""),"",C39*IF(D39="Yes",1,IF(D39="In Progress",0.5,IF(D39="N",0,"")))) | J39: Pending input, review or decision from WK Team.
A40: Data quality / missing-field clarifications | B40: Resolve unclear or missing source data | E40: =IF(OR(NOT(ISNUMBER(C40)),D40=""),"",C40*IF(D40="Yes",1,IF(D40="In Progress",0.5,IF(D40="N",0,"")))) | J40: Pending input, review or decision from WK Team.
A41: PMS changes: WK decisions | B41: WK decisions on requested PMS changes | E41: =IF(OR(NOT(ISNUMBER(C41)),D41=""),"",C41*IF(D41="Yes",1,IF(D41="In Progress",0.5,IF(D41="N",0,"")))) | J41: Pending input, review or decision from WK Team.
A42: WK team: choose Yes, In Progress or N. Scores calculate from the assigned weights; blank status means not assessed. Unweighted review lines are outside the 100% total.
A44: 05 / WORK ORDER SUMMARY — SAIL PMS
A45: Measure | B45: WO count | C45: Status | D45: Updated | E45: Notes
...
