Workbook

Sheet Dashboard
A1: SAIL PMS | PROJECT PROGRESS | U1: Activity status | V1: Count | X1: Critical category | Y1: Received | Z1: Not received
U2: Completed | V2: =COUNTIF('Update Tracker'!$E$29:$E$40,"Completed") -> 0 | X2: Components | Y2: =IF(ISNUMBER('Update Tracker'!C22),'Update Tracker'!C22,"") | Z2: =IF(ISNUMBER('Update Tracker'!D22),'Update Tracker'!D22,"")
A3: Stakeholder view / Data percentages are weighted: Components 30%, Jobs 30%, Spares 30%, Stores 10% (Maker list excluded). Enter confirmed counts and client actions on Update Tracker. | U3: Open | V3: =COUNTIF('Update Tracker'!$E$29:$E$40,"Not Started")+COUNTIF('Update Tracker'!$E$29:$E$40,"In Progress")+COUNTIF('Update Tracker'!$E$29:$E$40,"Partially Completed")+COUNTIF('Update Tracker'!$E$29:$E$40,"Pending Client Input")+COUNTIF('Update Tracker'!$E$29:$E$40,"Pending Client Action")+COUNTIF('Update Tracker'!$E$29:$E$40,"Pending SAIL Action")+COUNTIF('Update Tracker'!$E$29:$E$40,"Pending Review")+COUNTIF('Update Tracker'!$E$29:$E$40,"On Hold") -> 0 | X3: Spares | Y3: =IF(ISNUMBER('Update Tracker'!C23),'Update Tracker'!C23,"") | Z3: =IF(ISNUMBER('Update Tracker'!D23),'Update Tracker'!D23,"")
U4: Not Applicable | V4: =COUNTIF('Update Tracker'!$E$29:$E$40,"Not Applicable") -> 0 | X4: Jobs | Y4: =IF(ISNUMBER('Update Tracker'!C24),'Update Tracker'!C24,"") | Z4: =IF(ISNUMBER('Update Tracker'!D24),'Update Tracker'!D24,"")
B5: Reporting period | G5: Last updated | U5: Not assessed | V5: =COUNTA('Update Tracker'!$A$29:$A$40)-COUNTA('Update Tracker'!$E$29:$E$40) -> 12
B6: Responsible person | G6: Reporting to / audience
B8: SAIL TEAM / DELIVERY | G8: CLIENT SIDE / ACTIONS TO CONFIRM | J8: CLIENT-SIDE ACTIVITY STATUS
B10: Data received (weighted) | C10: 30 / 30 / 30 / 10 weight | D10: =IF(AND(COUNT('Update Tracker'!B7:B10)=4,COUNT('Update Tracker'!C7:C10)=4,COUNTIF('Update Tracker'!B7:B10,">0")=4,SUMPRODUCT(--('Update Tracker'!C7:C10>=0))=4,SUMPRODUCT(--('Update Tracker'!C7:C10<='Update Tracker'!B7:B10))=4),0.3*'Update Tracker'!C7/'Update Tracker'!B7+0.3*'Update Tracker'!C8/'Update Tracker'!B8+0.3*'Update Tracker'!C9/'Update Tracker'!B9+0.1*'Update Tracker'!C10/'Update Tracker'!B10,"") | G10: Open items (confirmed) | I10: =IF(COUNTA('Update Tracker'!$E$29:$E$40)=0,"",COUNTIF('Update Tracker'!$E$29:$E$40,"Not Started")+COUNTIF('Update Tracker'!$E$29:$E$40,"In Progress")+COUNTIF('Update Tracker'!$E$29:$E$40,"Partially Completed")+COUNTIF('Update Tracker'!$E$29:$E$40,"Pending Client Input")+COUNTIF('Update Tracker'!$E$29:$E$40,"Pending Client Action")+COUNTIF('Update Tracker'!$E$29:$E$40,"Pending SAIL Action")+COUNTIF('Update Tracker'!$E$29:$E$40,"Pending Review")+COUNTIF('Update Tracker'!$E$29:$E$40,"On Hold"))
B12: Data loaded (weighted) | C12: 30 / 30 / 30 / 10 weight | D12: =IF(AND(COUNT('Update Tracker'!B7:B10)=4,COUNT('Update Tracker'!C7:C10)=4,COUNT('Update Tracker'!D7:D10)=4,COUNTIF('Update Tracker'!B7:B10,">0")=4,SUMPRODUCT(--('Update Tracker'!C7:C10>=0))=4,SUMPRODUCT(--('Update Tracker'!C7:C10<='Update Tracker'!B7:B10))=4,SUMPRODUCT(--('Update Tracker'!D7:D10>=0))=4,SUMPRODUCT(--('Update Tracker'!D7:D10<='Update Tracker'!C7:C10))=4),0.3*'Update Tracker'!D7/'Update Tracker'!B7+0.3*'Update Tracker'!D8/'Update Tracker'!B8+0.3*'Update Tracker'!D9/'Update Tracker'!B9+0.1*'Update Tracker'!D10/'Update Tracker'!B10,"") | G12: Activities without status | I12: =COUNTA('Update Tracker'!$A$29:$A$40)-COUNTA('Update Tracker'!$E$29:$E$40) -> 12
B14: Missing jobs | C14: Components affected | D14: =IF(ISNUMBER('Update Tracker'!B16),'Update Tracker'!B16,"") | G14: Completed activities | I14: =IF(COUNTA('Update Tracker'!$E$29:$E$40)=0,"",COUNTIF('Update Tracker'!$E$29:$E$40,"Completed"))
B16: Missing spares | C16: Components affected | D16: =IF(ISNUMBER('Update Tracker'!B17),'Update Tracker'!B17,"") | G16: Only confirmed statuses count as open or complete. Unassessed activities are listed separately; they are not assumed pending.
B18: Critical items received | C18: Received / expected | D18: =IF(AND(COUNT('Update Tracker'!B22:B24)=3,COUNT('Update Tracker'!C22:C24)=3,SUM('Update Tracker'!B22:B24)>0,SUMPRODUCT(--('Update Tracker'!C22:C24<='Update Tracker'!B22:B24))=3),SUM('Update Tracker'!C22:C24)/SUM('Update Tracker'!B22:B24),"")
B20: WOs generated till now | C20: Cumulative count | D20: =IF(ISNUMBER('Update Tracker'!B46),'Update Tracker'!B46,"") | G20: CLIENT STATUS / REMARKS | J20: CRITICAL ITEMS / RECEIPT
B22: RH machinery updated | C22: Vessel updated / created | D22: =IF(ISNUMBER('Update Tracker'!E56),'Update Tracker'!E56,"")
B23: WO status counts can overlap. Repeated cycles can produce several WOs per job; no jobs-based percentage.
B25: REPORTING NOTES / EDITABLE
B26: Key completed points
B28: Pending points / next actions
B30: Major risks / gaps
B32: Other remarks
B34: No unrelated metrics are averaged. Aggregate percentages require all applicable counts; blank KPIs mean not confirmed, not zero.
B35: WORK ORDERS / RH MACHINERY SNAPSHOT
B36: Due | D36: =IF(ISNUMBER('Update Tracker'!B47),'Update Tracker'!B47,"") | G36: Overdue | I36: =IF(ISNUMBER('Update Tracker'!B48),'Update Tracker'!B48,"")
B37: Active | D37: =IF(ISNUMBER('Update Tracker'!B49),'Update Tracker'!B49,"") | G37: Pending approval | I37: =IF(ISNUMBER('Update Tracker'!B50),'Update Tracker'!B50,"") | J37: Enter total and received counts for Critical Components, Spares and Jobs to populate this chart.
B38: Completed | D38: =IF(ISNUMBER('Update Tracker'!B51),'Update Tracker'!B51,"") | G38: RH machinery created | I38: =IF(ISNUMBER('Update Tracker'!B56),'Update Tracker'!B56,"")
B39: Vessel RH details updated | D39: =IF(ISNUMBER('Update Tracker'!C56),'Update Tracker'!C56,"") | G39: RH not updated | I39: =IF(ISNUMBER('Update Tracker'!D56),'Update Tracker'!D56,"")

Sheet Update Tracker
A1: SAIL PMS | UPDATE TRACKER
A3: Yellow = editable input • Pale blue = calculated • Blank = not confirmed; enter 0 only when confirmed. All quantities are whole, nonnegative counts.
A5: 01 / SAIL TEAM — DATA RECEIVED & LOADED
A6: Data category | B6: Total expected | C6: Received | D6: Loaded in SAIL | E6: Not received | F6: Received % | G6: Loaded % | H6: Status | I6: Owner | J6: Last updated | K6: Target date | L6: Remarks / evidence
A7: Components | E7: =IF(AND(ISNUMBER(B7),ISNUMBER(C7),C7<=B7),B7-C7,"") | F7: =IF(AND(ISNUMBER(C7),ISNUMBER(B7),B7>0,C7<=B7),C7/B7,"") | G7: =IF(AND(ISNUMBER(D7),ISNUMBER(B7),B7>0,D7<=B7),D7/B7,"")
A8: Jobs | E8: =IF(AND(ISNUMBER(B8),ISNUMBER(C8),C8<=B8),B8-C8,"") | F8: =IF(AND(ISNUMBER(C8),ISNUMBER(B8),B8>0,C8<=B8),C8/B8,"") | G8: =IF(AND(ISNUMBER(D8),ISNUMBER(B8),B8>0,D8<=B8),D8/B8,"")
A9: Spares | E9: =IF(AND(ISNUMBER(B9),ISNUMBER(C9),C9<=B9),B9-C9,"") | F9: =IF(AND(ISNUMBER(C9),ISNUMBER(B9),B9>0,C9<=B9),C9/B9,"") | G9: =IF(AND(ISNUMBER(D9),ISNUMBER(B9),B9>0,D9<=B9),D9/B9,"")
A10: Stores | E10: =IF(AND(ISNUMBER(B10),ISNUMBER(C10),C10<=B10),B10-C10,"") | F10: =IF(AND(ISNUMBER(C10),ISNUMBER(B10),B10>0,C10<=B10),C10/B10,"") | G10: =IF(AND(ISNUMBER(D10),ISNUMBER(B10),B10>0,D10<=B10),D10/B10,"")
A11: Maker list | E11: =IF(AND(ISNUMBER(B11),ISNUMBER(C11),C11<=B11),B11-C11,"") | F11: =IF(AND(ISNUMBER(C11),ISNUMBER(B11),B11>0,C11<=B11),C11/B11,"") | G11: =IF(AND(ISNUMBER(D11),ISNUMBER(B11),B11>0,D11<=B11),D11/B11,"")
A12: Dashboard data % = Components 30% + Jobs 30% + Spares 30% + Stores 10%; Maker list is excluded. All four expected counts must be confirmed and greater than zero; missing or zero denominators keep the weighted KPI blank.
A14: 02 / SAIL TEAM — COMPONENTS MISSING JOBS OR SPARES
A15: Gap | B15: No. of components | C15: Affected component IDs / names | G15: Status | H15: Owner | I15: Target date | J15: Last updated | K15: Next action / remarks
A16: Missing jobs
A17: Missing spares
A18: List affected components by ID or name. A component missing both jobs and spares may appear in both rows; these counts must not be added together.
A20: 03 / SAIL TEAM — CRITICAL COMPONENTS, SPARES & JOBS RECEIPT
A21: Critical category | B21: Total expected | C21: Received | D21: Not received | E21: Received % | F21: Status | G21: Owner | H21: Last updated | I21: Target date | J21: Remarks / evidence
A22: Critical Components | D22: =IF(AND(ISNUMBER(B22),ISNUMBER(C22),C22<=B22),B22-C22,"") | E22: =IF(AND(ISNUMBER(C22),ISNUMBER(B22),B22>0,C22<=B22),C22/B22,"")
A23: Critical Spares | D23: =IF(AND(ISNUMBER(B23),ISNUMBER(C23),C23<=B23),B23-C23,"") | E23: =IF(AND(ISNUMBER(C23),ISNUMBER(B23),B23>0,C23<=B23),C23/B23,"")
A24: Critical Jobs | D24: =IF(AND(ISNUMBER(B24),ISNUMBER(C24),C24<=B24),B24-C24,"") | E24: =IF(AND(ISNUMBER(C24),ISNUMBER(B24),B24>0,C24<=B24),C24/B24,"")
A25: Critical receipt is tracked separately from overall data receipt. Blank = unconfirmed; enter 0 only when confirmed. No RH marking or approval metrics are included in this action sheet.
A27: 04 / CLIENT-SIDE ACTIVITIES — INPUTS, REVIEWS & DECISIONS TO CONFIRM
A28: Activity / requirement | B28: Total required | C28: Done / supplied | D28: Remaining | E28: Status | F28: Priority | G28: Owner | H28: Target date | I28: Completed date | J28: Last updated | K28: Next action / remarks
A29: Equipment register / source data | D29: =IF(AND(ISNUMBER(B29),ISNUMBER(C29),C29<=B29),B29-C29,"")
A30: Maker manuals collection | D30: =IF(AND(ISNUMBER(B30),ISNUMBER(C30),C30<=B30),B30-C30,"")
A31: Supporting documentation | D31: =IF(AND(ISNUMBER(B31),ISNUMBER(C31),C31<=B31),B31-C31,"")
A32: Task procedures / instructions | D32: =IF(AND(ISNUMBER(B32),ISNUMBER(C32),C32<=B32),B32-C32,"")
A33: PMS interval verification | D33: =IF(AND(ISNUMBER(B33),ISNUMBER(C33),C33<=B33),B33-C33,"")
A34: Spare parts source data | D34: =IF(AND(ISNUMBER(B34),ISNUMBER(C34),C34<=B34),B34-C34,"")
A35: Component-job-spare mapping inputs | D35: =IF(AND(ISNUMBER(B35),ISNUMBER(C35),C35<=B35),B35-C35,"")
A36: Criticality / risk review | D36: =IF(AND(ISNUMBER(B36),ISNUMBER(C36),C36<=B36),B36-C36,"")
A37: Class / statutory task review | D37: =IF(AND(ISNUMBER(B37),ISNUMBER(C37),C37<=B37),B37-C37,"")
A38: SMS / final verification | D38: =IF(AND(ISNUMBER(B38),ISNUMBER(C38),C38<=B38),B38-C38,"")
A39: Data quality / missing-field clarifications | D39: =IF(AND(ISNUMBER(B39),ISNUMBER(C39),C39<=B39),B39-C39,"")
A40: PMS changes: client decisions | D40: =IF(AND(ISNUMBER(B40),ISNUMBER(C40),C40<=B40),B40-C40,"")
A41: Client activities are a checklist, not assumed open or assigned. Leave unconfirmed owners, quantities, dates and statuses blank.
A44: 05 / SAIL TEAM — WORK ORDERS GENERATED TILL NOW
A45: Measure | B45: No. of WOs | C45: Status | D45: Owner | E45: Last updated | F45: Remarks / evidence
A46: Generated till now
A47: Due
...
